Workbook

Sheet Assumptions
A1: ANAROCK GTM Financial Model -- Meda East Winds
A2: All inputs on this sheet drive the entire model. Change any value below and all sheets recalculate.
A4: PROJECT PARAMETERS
A5: Parameter | B5: Value | C5: Unit | D5: Notes
A6: Total Saleable Area | B6: 800000 | C6: sft | D6: Net saleable area
A7: Average Apartment Size | B7: 1476 | C7: sft | D7: Weighted average across tiers
A8: Total Units (calculated) | B8: =ROUND($B$6/$B$7,0) | C8: Units | D8: =Total Area / Avg Size
A10: --- Tier 1: Value Entry (2BHK) ---
A11: T1 Units | B11: 220 | C11: Units | D11: Compact 2BHK
A12: T1 Avg Size | B12: 1050 | C12: sft | D12: Per unit
A13: T1 Base Price | B13: 8500 | C13: Rs/sft | D13: Launch price
A14: T1 Effective Price | B14: 9200 | C14: Rs/sft | D14: After premiums
A16: --- Tier 2: Core Premium (3BHK) ---
A17: T2 Units | B17: 280 | C17: Units | D17: Premium 3BHK
A18: T2 Avg Size | B18: 1600 | C18: sft | D18: Per unit
A19: T2 Base Price | B19: 10800 | C19: Rs/sft | D19: Launch price
A20: T2 Effective Price | B20: 11500 | C20: Rs/sft | D20: After premiums
A22: --- Tier 3: Signature Luxury ---
A23: T3 Units | B23: 42 | C23: Units | D23: Penthouses / 4BHK
A24: T3 Avg Size | B24: 2800 | C24: sft | D24: Per unit
A25: T3 Base Price | B25: 12500 | C25: Rs/sft | D25: Launch price
A26: T3 Effective Price | B26: 14200 | C26: Rs/sft | D26: After premiums
A28: --- Cost Parameters ---
A29: Land Acquisition Cost | B29: 3100 | C29: Rs/sft | D29: Upfront equity
A30: Construction Cost (All-in) | B30: 4200 | C30: Rs/sft | D30: Incl. amenities, MEP, finishing
A31: Statutory & Approvals | B31: 8 | C31: Cr | D31: RERA, BDA, BBMP
A32: Contingency % | B32: 2 | C32: % | D32: As % of hard cost
A34: --- Financing ---
A35: Debt LTV Ratio | B35: 65 | C35: % | D35: Loan-to-value
A36: Debt Interest Rate | B36: 9.5 | C36: % | D36: Annual
A37: Loan Tenure | B37: 36 | C37: Months | D37: Construction finance
A39: --- Anarock GTM Fees ---
A40: Brokerage Commission Rate | B40: 1.5 | C40: % | D40: Of GTV per sale
A41: Marketing Budget Rate | B41: 0.8 | C41: % | D41: Of GTV
A42: AI Platform Monthly Fee | B42: 3 | C42: Lakhs/mo | D42: Astra, Genie, CP Ranker
A43: CP Mobilization (One-time) | B43: 25 | C43: Lakhs | D43: 200 broker onboarding
A44: Performance Bonus Rate | B44: 0.25 | C44: % | D44: Incremental if velocity >15/mo
A46: --- Sales Velocity ---
A47: Target Monthly Velocity | B47: 12 | C47: Units/mo | D47: Gate 4 threshold
A48: Pre-Launch Soft Bookings % | B48: 15 | C48: % | D48: Gate 3: % of total units
...

Sheet Revenue Waterfall
A1: Revenue Waterfall -- Barbell Pricing Architecture
A2: All cells reference Assumptions sheet. Change tier inputs to recalculate.
A4: Tier | B4: Configuration | C4: Unit Count | D4: Avg Size (sft) | E4: Base Price (Rs/sft) | F4: Effective Price (Rs/sft) | G4: Avg Ticket (Cr) | H4: Tier GTV (Cr) | I4: % of Total GTV
A5: Value Entry | B5: Compact 2 BHK | C5: ='Assumptions'!$B$11 | D5: ='Assumptions'!$B$12 | E5: ='Assumptions'!$B$13 | F5: ='Assumptions'!$B$14 | G5: ='Assumptions'!$B$70/'Assumptions'!$B$11 | H5: ='Assumptions'!$B$70 | I5: ='Assumptions'!$B$70/'Assumptions'!$B$73
A6: Core Premium | B6: Premium 3 BHK | C6: ='Assumptions'!$B$17 | D6: ='Assumptions'!$B$18 | E6: ='Assumptions'!$B$19 | F6: ='Assumptions'!$B$20 | G6: ='Assumptions'!$B$71/'Assumptions'!$B$17 | H6: ='Assumptions'!$B$71 | I6: ='Assumptions'!$B$71/'Assumptions'!$B$73
A7: Signature Luxury | B7: Penthouses / 4 BHK | C7: ='Assumptions'!$B$23 | D7: ='Assumptions'!$B$24 | E7: ='Assumptions'!$B$25 | F7: ='Assumptions'!$B$26 | G7: ='Assumptions'!$B$72/'Assumptions'!$B$23 | H7: ='Assumptions'!$B$72 | I7: ='Assumptions'!$B$72/'Assumptions'!$B$73
A8: TOTAL / BLENDED | C8: ='Assumptions'!$B$74 | D8: ='Assumptions'!$B$7 | F8: ='Assumptions'!$B$75 | G8: ='Assumptions'!$B$76 | H8: ='Assumptions'!$B$73 | I8: 1
A10: Revenue Phasing by GTM Stage
A11: GTM Stage | B11: Timeline | C11: % of Units Sold | D11: Units Sold | E11: Revenue (Cr) | F11: Cumulative Units | G11: Cumulative Revenue (Cr) | H11: % GTV Achieved | I11: Avg Velocity (units/mo) | J11: Months
A12: S1: Pre-Mandate Discovery | B12: Month 1-2 | C12: 0 | D12: =ROUND($C$12*'Assumptions'!$B$74,0) | E12: =$C$12*'Assumptions'!$B$73 | F12: =$D$12 | G12: =$E$12 | H12: =$G$12/'Assumptions'!$B$73 | I12: =IF($J$12=0,0,$D$12/$J$12) | J12: 2
A13: S2: GTM & Creative Prep | B13: Month 3-4 | C13: 0 | D13: =ROUND($C$13*'Assumptions'!$B$74,0) | E13: =$C$13*'Assumptions'!$B$73 | F13: =$F$12+$D$13 | G13: =$G$12+$E$13 | H13: =$G$13/'Assumptions'!$B$73 | I13: =IF($J$13=0,0,$D$13/$J$13) | J13: 2
A14: S3: Pre-Launch Soft Bookings | B14: Month 5 | C14: 0.15 | D14: =ROUND($C$14*'Assumptions'!$B$74,0) | E14: =$C$14*'Assumptions'!$B$73 | F14: =$F$13+$D$14 | G14: =$G$13+$E$14 | H14: =$G$14/'Assumptions'!$B$73 | I14: =IF($J$14=0,0,$D$14/$J$14) | J14: 1
A15: S4: Public Launch (M6-M12) | B15: Month 6-12 | C15: 0.27 | D15: =ROUND($C$15*'Assumptions'!$B$74,0) | E15: =$C$15*'Assumptions'!$B$73 | F15: =$F$14+$D$15 | G15: =$G$14+$E$15 | H15: =$G$15/'Assumptions'!$B$73 | I15: =IF($J$15=0,0,$D$15/$J$15) | J15: 7
A16: S4: Sustenance (M13-M24) | B16: Month 13-24 | C16: 0.31 | D16: =ROUND($C$16*'Assumptions'!$B$74,0) | E16: =$C$16*'Assumptions'!$B$73 | F16: =$F$15+$D$16 | G16: =$G$15+$E$16 | H16: =$G$16/'Assumptions'!$B$73 | I16: =IF($J$16=0,0,$D$16/$J$16) | J16: 12
A17: S4: Sustenance (M25-M36) | B17: Month 25-36 | C17: 0.205 | D17: =ROUND($C$17*'Assumptions'!$B$74,0) | E17: =$C$17*'Assumptions'!$B$73 | F17: =$F$16+$D$17 | G17: =$G$16+$E$17 | H17: =$G$17/'Assumptions'!$B$73 | I17: =IF($J$17=0,0,$D$17/$J$17) | J17: 12
A18: S4: Wrapex & Final | B18: Month 37-42 | C18: 0.065 | D18: =ROUND($C$18*'Assumptions'!$B$74,0) | E18: =$C$18*'Assumptions'!$B$73 | F18: =$F$17+$D$18 | G18: =$G$17+$E$18 | H18: =$G$18/'Assumptions'!$B$73 | I18: =IF($J$18=0,0,$D$18/$J$18) | J18: 6

Sheet Cost Structure & PnL
A1: Project Cost Structure & Developer P&L
A2: All costs computed from Assumptions inputs. Change rates to see P&L impact.
A4: Cost Category | B4: Rate / Basis | C4: Total Cost (Cr) | D4: % of GTV | E4: % of Total Cost | F4: Notes
A5: Land Acquisition (Equity) | B5: ='Assumptions'!$B$29&" Rs/sft" | C5: ='Assumptions'!$B$78 | D5: ='Assumptions'!$B$78/'Assumptions'!$B$73 | E5: =IF('Assumptions'!$B$91=0,0,ABS($C$5)/'Assumptions'!$B$91) | F5: Upfront equity outlay
A6: Construction Cost (All-in) | B6: ='Assumptions'!$B$30&" Rs/sft" | C6: ='Assumptions'!$B$79 | D6: ='Assumptions'!$B$79/'Assumptions'!$B$73 | E6: =IF('Assumptions'!$B$91=0,0,ABS($C$6)/'Assumptions'!$B$91) | F6: Incl. amenities, MEP
A7: TOTAL HARD COSTS | C7: ='Assumptions'!$B$80 | D7: ='Assumptions'!$B$80/'Assumptions'!$B$73 | E7: =IF('Assumptions'!$B$91=0,0,ABS($C$7)/'Assumptions'!$B$91)
A9: Statutory & Approvals | B9: Fixed | C9: ='Assumptions'!$B$31 | D9: ='Assumptions'!$B$31/'Assumptions'!$B$73 | E9: =IF('Assumptions'!$B$91=0,0,ABS($C$9)/'Assumptions'!$B$91) | F9: RERA, BDA, BBMP
A10: Contingency | B10: ='Assumptions'!$B$32&"% of hard costs" | C10: ='Assumptions'!$B$81 | D10: ='Assumptions'!$B$81/'Assumptions'!$B$73 | E10: =IF('Assumptions'!$B$91=0,0,ABS($C$10)/'Assumptions'!$B$91) | F10: Risk buffer
A12: Anarock Brokerage | B12: ='Assumptions'!$B$40&"% of GTV" | C12: ='Assumptions'!$B$83 | D12: ='Assumptions'!$B$83/'Assumptions'!$B$73 | E12: =IF('Assumptions'!$B$91=0,0,ABS($C$12)/'Assumptions'!$B$91) | F12: Per sale closure
A13: Anarock Marketing | B13: ='Assumptions'!$B$41&"% of GTV" | C13: ='Assumptions'!$B$84 | D13: ='Assumptions'!$B$84/'Assumptions'!$B$73 | E13: =IF('Assumptions'!$B$91=0,0,ABS($C$13)/'Assumptions'!$B$91) | F13: Digital + OOH
A14: AI Platform License | B14: ='Assumptions'!$B$42&" L/mo x 42 mo" | C14: ='Assumptions'!$B$85 | D14: ='Assumptions'!$B$85/'Assumptions'!$B$73 | E14: =IF('Assumptions'!$B$91=0,0,ABS($C$14)/'Assumptions'!$B$91) | F14: Astra, Genie, CP Ranker
A15: CP Mobilization | B15: One-time | C15: ='Assumptions'!$B$86 | D15: ='Assumptions'!$B$86/'Assumptions'!$B$73 | E15: =IF('Assumptions'!$B$91=0,0,ABS($C$15)/'Assumptions'!$B$91) | F15: Broker onboarding
A16: Performance Bonus | B16: ='Assumptions'!$B$44&"% of GTV" | C16: ='Assumptions'!$B$87 | D16: ='Assumptions'!$B$87/'Assumptions'!$B$73 | E16: =IF('Assumptions'!$B$91=0,0,ABS($C$16)/'Assumptions'!$B$91) | F16: If velocity >15/mo
A17: TOTAL ANAROCK GTM COST | C17: ='Assumptions'!$B$88 | D17: ='Assumptions'!$B$88/'Assumptions'!$B$73 | E17: =IF('Assumptions'!$B$91=0,0,ABS($C$17)/'Assumptions'!$B$91)
A19: TOTAL PROJECT COST | C19: ='Assumptions'!$B$91 | D19: ='Assumptions'!$B$91/'Assumptions'!$B$73
A21: GROSS REVENUE (GTV) | C21: ='Assumptions'!$B$73 | D21: 1
A22: (-) Total Project Cost | C22: =-'Assumptions'!$B$91 | D22: =-'Assumptions'!$B$91/'Assumptions'!$B$73
A23: DEVELOPER NET PROFIT | C23: ='Assumptions'!$B$92 | D23: ='Assumptions'!$B$92/'Assumptions'!$B$73
A24: NET MARGIN % | C24: ='Assumptions'!$B$93/100

Sheet Cash Flow Projection
A1: Quarterly Cash Flow Projection -- 48 Month Lifecycle
A2: Inflows from sales, outflows for construction & GTM. Cumulative computed via formulas.
A4: Quarter | B4: Months | C4: GTM Stage | D4: % Units Sold | E4: Units Sold | F4: Sale Revenue (Cr) | G4: Construction Out (Cr) | H4: GTM Cost Out (Cr) | I4: Net Cash Flow (Cr) | J4: Cumulative CF (Cr) | K4: Cumulative Units
A5: Q1 | B5: M1-M3 | C5: S1: Discovery | D5: 0 | E5: =ROUND($D$5*'Assumptions'!$B$74,0) | F5: =$D$5*'Assumptions'!$B$73 | G5: ='Assumptions'!$B$79*0.0 | H5: ='Assumptions'!$B$88*(80/2750) | I5: =$F$5-$G$5-$H$5 | J5: =$I$5 | K5: =$E$5
A6: Q2 | B6: M4-M6 | C6: S2-S3: Prep + Soft | D6: 0.15 | E6: =ROUND($D$6*'Assumptions'!$B$74,0) | F6: =$D$6*'Assumptions'!$B$73 | G6: ='Assumptions'!$B$79*0.083 | H6: ='Assumptions'!$B$88*(320/2750) | I6: =$F$6-$G$6-$H$6 | J6: =$J$5+$I$6 | K6: =$K$5+$E$6
A7: Q3 | B7: M7-M9 | C7: S4: Public Launch | D7: 0.11 | E7: =ROUND($D$7*'Assumptions'!$B$74,0) | F7: =$D$7*'Assumptions'!$B$73 | G7: ='Assumptions'!$B$79*0.083 | H7: ='Assumptions'!$B$88*(450/2750) | I7: =$F$7-$G$7-$H$7 | J7: =$J$6+$I$7 | K7: =$K$6+$E$7
A8: Q4 | B8: M10-M12 | C8: S4: Launch Momentum | D8: 0.16 | E8: =ROUND($D$8*'Assumptions'!$B$74,0) | F8: =$D$8*'Assumptions'!$B$73 | G8: ='Assumptions'!$B$79*0.083 | H8: ='Assumptions'!$B$88*(420/2750) | I8: =$F$8-$G$8-$H$8 | J8: =$J$7+$I$8 | K8: =$K$7+$E$8
A9: Q5 | B9: M13-M15 | C9: S4: Sustenance | D9: 0.09 | E9: =ROUND($D$9*'Assumptions'!$B$74,0) | F9: =$D$9*'Assumptions'!$B$73 | G9: ='Assumptions'!$B$79*0.083 | H9: ='Assumptions'!$B$88*(280/2750) | I9: =$F$9-$G$9-$H$9 | J9: =$J$8+$I$9 | K9: =$K$8+$E$9
A10: Q6 | B10: M16-M18 | C10: S4: Sustenance | D10: 0.08 | E10: =ROUND($D$10*'Assumptions'!$B$74,0) | F10: =$D$10*'Assumptions'!$B$73 | G10: ='Assumptions'!$B$79*0.083 | H10: ='Assumptions'!$B$88*(250/2750) | I10: =$F$10-$G$10-$H$10 | J10: =$J$9+$I$10 | K10: =$K$9+$E$10
A11: Q7 | B11: M19-M21 | C11: S4: Sustenance | D11: 0.075 | E11: =ROUND($D$11*'Assumptions'!$B$74,0) | F11: =$D$11*'Assumptions'!$B$73 | G11: ='Assumptions'!$B$79*0.083 | H11: ='Assumptions'!$B$88*(220/2750) | I11: =$F$11-$G$11-$H$11 | J11: =$J$10+$I$11 | K11: =$K$10+$E$11
A12: Q8 | B12: M22-M24 | C12: S4: Sustenance | D12: 0.07 | E12: =ROUND($D$12*'Assumptions'!$B$74,0) | F12: =$D$12*'Assumptions'!$B$73 | G12: ='Assumptions'!$B$79*0.083 | H12: ='Assumptions'!$B$88*(200/2750) | I12: =$F$12-$G$12-$H$12 | J12: =$J$11+$I$12 | K12: =$K$11+$E$12
A13: Q9 | B13: M25-M27 | C13: S4: Sustenance | D13: 0.06 | E13: =ROUND($D$13*'Assumptions'!$B$74,0) | F13: =$D$13*'Assumptions'!$B$73 | G13: ='Assumptions'!$B$79*0.065 | H13: ='Assumptions'!$B$88*(150/2750) | I13: =$F$13-$G$13-$H$13 | J13: =$J$12+$I$13 | K13: =$K$12+$E$13
A14: Q10 | B14: M28-M30 | C14: S4: Sustenance | D14: 0.055 | E14: =ROUND($D$14*'Assumptions'!$B$74,0) | F14: =$D$14*'Assumptions'!$B$73 | G14: ='Assumptions'!$B$79*0.065 | H14: ='Assumptions'!$B$88*(120/2750) | I14: =$F$14-$G$14-$H$14 | J14: =$J$13+$I$14 | K14: =$K$13+$E$14
A15: Q11 | B15: M31-M33 | C15: S4: Sustenance | D15: 0.05 | E15: =ROUND($D$15*'Assumptions'!$B$74,0) | F15: =$D$15*'Assumptions'!$B$73 | G15: ='Assumptions'!$B$79*0.065 | H15: ='Assumptions'!$B$88*(100/2750) | I15: =$F$15-$G$15-$H$15 | J15: =$J$14+$I$15 | K15: =$K$14+$E$15
A16: Q12 | B16: M34-M36 | C16: S4: Winding Down | D16: 0.04 | E16: =ROUND($D$16*'Assumptions'!$B$74,0) | F16: =$D$16*'Assumptions'!$B$73 | G16: ='Assumptions'!$B$79*0.065 | H16: ='Assumptions'!$B$88*(80/2750) | I16: =$F$16-$G$16-$H$16 | J16: =$J$15+$I$16 | K16: =$K$15+$E$16
A17: Q13 | B17: M37-M39 | C17: Wrapex | D17: 0.035 | E17: =ROUND($D$17*'Assumptions'!$B$74,0) | F17: =$D$17*'Assumptions'!$B$73 | G17: ='Assumptions'!$B$79*0.054000000000000006 | H17: ='Assumptions'!$B$88*(50/2750) | I17: =$F$17-$G$17-$H$17 | J17: =$J$16+$I$17 | K17: =$K$16+$E$17
A18: Q14 | B18: M40-M42 | C18: Wrapex | D18: 0.025 | E18: =ROUND($D$18*'Assumptions'!$B$74,0) | F18: =$D$18*'Assumptions'!$B$73 | G18: ='Assumptions'!$B$79*0.054000000000000006 | H18: ='Assumptions'!$B$88*(30/2750) | I18: =$F$18-$G$18-$H$18 | J18: =$J$17+$I$18 | K18: =$K$17+$E$18
A19: Q15 | B19: M43-M45 | C19: Handover | D19: 0 | E19: =ROUND($D$19*'Assumptions'!$B$74,0) | F19: =$D$19*'Assumptions'!$B$73 | G19: ='Assumptions'!$B$79*0.03 | H19: ='Assumptions'!$B$88*(0/2750) | I19: =$F$19-$G$19-$H$19 | J19: =$J$18+$I$19 | K19: =$K$18+$E$19
A20: Q16 | B20: M46-M48 | C20: Final Handover | D20: 0 | E20: =ROUND($D$20*'Assumptions'!$B$74,0) | F20: =$D$20*'Assumptions'!$B$73 | G20: ='Assumptions'!$B$79*0.018000000000000002 | H20: ='Assumptions'!$B$88*(0/2750) | I20: =$F$20-$G$20-$H$20 | J20: =$J$19+$I$20 | K20: =$K$19+$E$20
A21: TOTAL | D21: =SUM($D$5:$D$20) | E21: =SUM($E$5:$E$20) | F21: =SUM($F$5:$F$20) | G21: =SUM($G$5:$G$20) | H21: =SUM($H$5:$H$20) | I21: =SUM($I$5:$I$20)

Sheet IRR & DSCR Analysis
A1: Developer Equity IRR & DSCR Sensitivity
A2: Matrix shows estimated IRR at various ASP x Velocity combos. Base case highlighted.
A4: IRR Sensitivity Matrix -- ASP vs. Sales Velocity
A5: ASP \ Velocity | B5: 8 u/mo | C5: 10 u/mo | D5: 12 u/mo (Target) | E5: 15 u/mo | F5: 18 u/mo
A6: Rs 8,500 | B6: =((8500*'Assumptions'!$B$6/10000000 - 'Assumptions'!$B$80 - 'Assumptions'!$B$31 - 'Assumptions'!$B$81 - 'Assumptions'!$B$88) / 'Assumptions'!$B$78) / ('Assumptions'!$B$74/(8*12)) | C6: =((8500*'Assumptions'!$B$6/10000000 - 'Assumptions'!$B$80 - 'Assumptions'!$B$31 - 'Assumptions'!$B$81 - 'Assumptions'!$B$88) / 'Assumptions'!$B$78) / ('Assumptions'!$B$74/(10*12)) | D6: =((8500*'Assumptions'!$B$6/10000000 - 'Assumptions'!$B$80 - 'Assumptions'!$B$31 - 'Assumptions'!$B$81 - 'Assumptions'!$B$88) / 'Assumptions'!$B$78) / ('Assumptions'!$B$74/(12*12)) | E6: =((8500*'Assumptions'!$B$6/10000000 - 'Assumptions'!$B$80 - 'Assumptions'!$B$31 - 'Assumptions'!$B$81 - 'Assumptions'!$B$88) / 'Assumptions'!$B$78) / ('Assumptions'!$B$74/(15*12)) | F6: =((8500*'Assumptions'!$B$6/10000000 - 'Assumptions'!$B$80 - 'Assumptions'!$B$31 - 'Assumptions'!$B$81 - 'Assumptions'!$B$88) / 'Assumptions'!$B$78) / ('Assumptions'!$B$74/(18*12))
A7: Rs 9,200 | B7: =((9200*'Assumptions'!$B$6/10000000 - 'Assumptions'!$B$80 - 'Assumptions'!$B$31 - 'Assumptions'!$B$81 - 'Assumptions'!$B$88) / 'Assumptions'!$B$78) / ('Assumptions'!$B$74/(8*12)) | C7: =((9200*'Assumptions'!$B$6/10000000 - 'Assumptions'!$B$80 - 'Assumptions'!$B$31 - 'Assumptions'!$B$81 - 'Assumptions'!$B$88) / 'Assumptions'!$B$78) / ('Assumptions'!$B$74/(10*12)) | D7: =((9200*'Assumptions'!$B$6/10000000 - 'Assumptions'!$B$80 - 'Assumptions'!$B$31 - 'Assumptions'!$B$81 - 'Assumptions'!$B$88) / 'Assumptions'!$B$78) / ('Assumptions'!$B$74/(12*12)) | E7: =((9200*'Assumptions'!$B$6/10000000 - 'Assumptions'!$B$80 - 'Assumptions'!$B$31 - 'Assumptions'!$B$81 - 'Assumptions'!$B$88) / 'Assumptions'!$B$78) / ('Assumptions'!$B$74/(15*12)) | F7: =((9200*'Assumptions'!$B$6/10000000 - 'Assumptions'!$B$80 - 'Assumptions'!$B$31 - 'Assumptions'!$B$81 - 'Assumptions'!$B$88) / 'Assumptions'!$B$78) / ('Assumptions'!$B$74/(18*12))
A8: Rs 10,200 (Base) | B8: =((10200*'Assumptions'!$B$6/10000000 - 'Assumptions'!$B$80 - 'Assumptions'!$B$31 - 'Assumptions'!$B$81 - 'Assumptions'!$B$88) / 'Assumptions'!$B$78) / ('Assumptions'!$B$74/(8*12)) | C8: =((10200*'Assumptions'!$B$6/10000000 - 'Assumptions'!$B$80 - 'Assumptions'!$B$31 - 'Assumptions'!$B$81 - 'Assumptions'!$B$88) / 'Assumptions'!$B$78) / ('Assumptions'!$B$74/(10*12)) | D8: =((10200*'Assumptions'!$B$6/10000000 - 'Assumptions'!$B$80 - 'Assumptions'!$B$31 - 'Assumptions'!$B$81 - 'Assumptions'!$B$88) / 'Assumptions'!$B$78) / ('Assumptions'!$B$74/(12*12)) | E8: =((10200*'Assumptions'!$B$6/10000000 - 'Assumptions'!$B$80 - 'Assumptions'!$B$31 - 'Assumptions'!$B$81 - 'Assumptions'!$B$88) / 'Assumptions'!$B$78) / ('Assumptions'!$B$74/(15*12)) | F8: =((10200*'Assumptions'!$B$6/10000000 - 'Assumptions'!$B$80 - 'Assumptions'!$B$31 - 'Assumptions'!$B$81 - 'Assumptions'!$B$88) / 'Assumptions'!$B$78) / ('Assumptions'!$B$74/(18*12))
A9: Rs 10,800 | B9: =((10800*'Assumptions'!$B$6/10000000 - 'Assumptions'!$B$80 - 'Assumptions'!$B$31 - 'Assumptions'!$B$81 - 'Assumptions'!$B$88) / 'Assumptions'!$B$78) / ('Assumptions'!$B$74/(8*12)) | C9: =((10800*'Assumptions'!$B$6/10000000 - 'Assumptions'!$B$80 - 'Assumptions'!$B$31 - 'Assumptions'!$B$81 - 'Assumptions'!$B$88) / 'Assumptions'!$B$78) / ('Assumptions'!$B$74/(10*12)) | D9: =((10800*'Assumptions'!$B$6/10000000 - 'Assumptions'!$B$80 - 'Assumptions'!$B$31 - 'Assumptions'!$B$81 - 'Assumptions'!$B$88) / 'Assumptions'!$B$78) / ('Assumptions'!$B$74/(12*12)) | E9: =((10800*'Assumptions'!$B$6/10000000 - 'Assumptions'!$B$80 - 'Assumptions'!$B$31 - 'Assumptions'!$B$81 - 'Assumptions'!$B$88) / 'Assumptions'!$B$78) / ('Assumptions'!$B$74/(15*12)) | F9: =((10800*'Assumptions'!$B$6/10000000 - 'Assumptions'!$B$80 - 'Assumptions'!$B$31 - 'Assumptions'!$B$81 - 'Assumptions'!$B$88) / 'Assumptions'!$B$78) / ('Assumptions'!$B$74/(18*12))
A10: Rs 11,500 | B10: =((11500*'Assumptions'!$B$6/10000000 - 'Assumptions'!$B$80 - 'Assumptions'!$B$31 - 'Assumptions'!$B$81 - 'Assumptions'!$B$88) / 'Assumptions'!$B$78) / ('Assumptions'!$B$74/(8*12)) | C10: =((11500*'Assumptions'!$B$6/10000000 - 'Assumptions'!$B$80 - 'Assumptions'!$B$31 - 'Assumptions'!$B$81 - 'Assumptions'!$B$88) / 'Assumptions'!$B$78) / ('Assumptions'!$B$74/(10*12)) | D10: =((11500*'Assumptions'!$B$6/10000000 - 'Assumptions'!$B$80 - 'Assumptions'!$B$31 - 'Assumptions'!$B$81 - 'Assumptions'!$B$88) / 'Assumptions'!$B$78) / ('Assumptions'!$B$74/(12*12)) | E10: =((11500*'Assumptions'!$B$6/10000000 - 'Assumptions'!$B$80 - 'Assumptions'!$B$31 - 'Assumptions'!$B$81 - 'Assumptions'!$B$88) / 'Assumptions'!$B$78) / ('Assumptions'!$B$74/(15*12)) | F10: =((11500*'Assumptions'!$B$6/10000000 - 'Assumptions'!$B$80 - 'Assumptions'!$B$31 - 'Assumptions'!$B$81 - 'Assumptions'!$B$88) / 'Assumptions'!$B$78) / ('Assumptions'!$B$74/(18*12))
B12: Green: Strong IRR zone (above base)
B13: Blue: Base case scenario
B14: Gray: Computed from Assumptions -- change inputs to update
A17: DSCR Scenario Analysis
A18: Scenario | B18: LTV % | C18: Debt (Cr) | D18: Interest % | E18: Annual Debt Svc (Cr) | F18: Annual NOI (Cr) | G18: DSCR | H18: Gate Status
A19: Conservative | B19: 0.6 | C19: ='Assumptions'!$B$73*$B$19 | D19: 0.095 | E19: =$C$19*$D$19 | F19: ='Assumptions'!$B$97 | G19: =$F$19/$E$19 | H19: =IF($G$19>=1.4,"CLEAR","BLOCKED")
A20: Base Case | B20: 0.65 | C20: ='Assumptions'!$B$73*$B$20 | D20: 0.095 | E20: =$C$20*$D$20 | F20: ='Assumptions'!$B$97 | G20: =$F$20/$E$20 | H20: =IF($G$20>=1.4,"CLEAR","BLOCKED")
A21: Aggressive | B21: 0.7 | C21: ='Assumptions'!$B$73*$B$21 | D21: 0.1 | E21: =$C$21*$D$21 | F21: ='Assumptions'!$B$97 | G21: =$F$21/$E$21 | H21: =IF($G$21>=1.4,"CLEAR","BLOCKED")
A22: Stressed | B22: 0.75 | C22: ='Assumptions'!$B$73*$B$22 | D22: 0.11 | E22: =$C$22*$D$22 | F22: ='Assumptions'!$B$97 | G22: =$F$22/$E$22 | H22: =IF($G$22>=1.4,"CLEAR","BLOCKED")
A23: Worst Case | B23: 0.8 | C23: ='Assumptions'!$B$73*$B$23 | D23: 0.115 | E23: =$C$23*$D$23 | F23: ='Assumptions'!$B$97 | G23: =$F$23/$E$23 | H23: =IF($G$23>=1.4,"CLEAR","BLOCKED")

Sheet Stage-Gate Budget
A1: GTM Stage-Gate Budget Tracker
A2: Budget column links to Assumptions. Actual Spend is user-input. Variance auto-calculates.
A4: Stage | B4: Activity | C4: Budget (Lakhs) | D4: Actual Spend (Lakhs) | E4: Variance (Lakhs) | F4: Var % | G4: Owner | H4: Status
A5: S1 | B5: Competitor Conjoint Analysis | C5: 15 | D5: 14.2 | E5: =$C$5-$D$5 | F5: =IF($C$5=0,0,$E$5/$C$5) | G5: Research
A6: S1 | B6: Micro-Market Demand Heatmap | C6: 8 | D6: 7.5 | E6: =$C$6-$D$6 | F6: =IF($C$6=0,0,$E$6/$C$6) | G6: Data Science
A7: S1 | B7: Financial Hurdle Model | C7: 5 | D7: 4.8 | E7: =$C$7-$D$7 | F7: =IF($C$7=0,0,$E$7/$C$7) | G7: Finance
A8: S1 | B8: Legal Due Diligence | C8: 12 | D8: 11.5 | E8: =$C$8-$D$8 | F8: =IF($C$8=0,0,$E$8/$C$8) | G8: Legal
B9: Stage 1 Subtotal | C9: =SUM($C$5:$C$8) | D9: =SUM($D$5:$D$8) | E9: =$C$9-$D$9 | F9: =IF($C$9=0,0,$E$9/$C$9)
A11: S2 | B11: Barbell Pricing Architecture | C11: 10 | D11: 9.8 | E11: =$C$11-$D$11 | F11: =IF($C$11=0,0,$E$11/$C$11) | G11: Pricing
A12: S2 | B12: Walk-in Genie AI Training | C12: 18 | D12: 12 | E12: =$C$12-$D$12 | F12: =IF($C$12=0,0,$E$12/$C$12) | G12: AI Team
A13: S2 | B13: CP Ranker & Mobilization | C13: 25 | D13: 15 | E13: =$C$13-$D$13 | F13: =IF($C$13=0,0,$E$13/$C$13) | G13: CP Ops
A14: S2 | B14: Site Experience Office | C14: 85 | D14: 45 | E14: =$C$14-$D$14 | F14: =IF($C$14=0,0,$E$14/$C$14) | G14: Developer
A15: S2 | B15: Creative Kit & Collaterals | C15: 30 | D15: 0 | E15: =$C$15-$D$15 | F15: =IF($C$15=0,0,$E$15/$C$15) | G15: Creative
A16: S2 | B16: RERA Registration Support | C16: 5 | D16: 4.5 | E16: =$C$16-$D$16 | F16: =IF($C$16=0,0,$E$16/$C$16) | G16: Legal
B17: Stage 2 Subtotal | C17: =SUM($C$11:$C$16) | D17: =SUM($D$11:$D$16) | E17: =$C$17-$D$17 | F17: =IF($C$17=0,0,$E$17/$C$17)
A19: S3 | B19: Concierge MVP Events (5x) | C19: 35 | D19: 0 | E19: =$C$19-$D$19 | F19: =IF($C$19=0,0,$E$19/$C$19) | G19: Sales Ops
A20: S3 | B20: Astra Platinum Integration | C20: 12 | D20: 0 | E20: =$C$20-$D$20 | F20: =IF($C$20=0,0,$E$20/$C$20) | G20: AI Team
A21: S3 | B21: EOI Token Campaign | C21: 45 | D21: 0 | E21: =$C$21-$D$21 | F21: =IF($C$21=0,0,$E$21/$C$21) | G21: Marketing
A22: S3 | B22: CP Launch Events | C22: 20 | D22: 0 | E22: =$C$22-$D$22 | F22: =IF($C$22=0,0,$E$22/$C$22) | G22: CP Ops
B23: Stage 3 Subtotal | C23: =SUM($C$19:$C$22) | D23: =SUM($D$19:$D$22) | E23: =$C$23-$D$23 | F23: =IF($C$23=0,0,$E$23/$C$23)
A25: S4 | B25: 360 Digital Campaign (Meta/Google) | C25: 180 | D25: 0 | E25: =$C$25-$D$25 | F25: =IF($C$25=0,0,$E$25/$C$25) | G25: Digital
A26: S4 | B26: Local OOH & Print | C26: 80 | D26: 0 | E26: =$C$26-$D$26 | F26: =IF($C$26=0,0,$E$26/$C$26) | G26: Media
A27: S4 | B27: n8n Lead Revival (Astra Phoenix) | C27: 15 | D27: 0 | E27: =$C$27-$D$27 | F27: =IF($C$27=0,0,$E$27/$C$27) | G27: AI Team
A28: S4 | B28: Mandate Health Dashboard | C28: 8 | D28: 0 | E28: =$C$28-$D$28 | F28: =IF($C$28=0,0,$E$28/$C$28) | G28: BI Team
A29: S4 | B29: CP Commission Pool | C29: 350 | D29: 0 | E29: =$C$29-$D$29 | F29: =IF($C$29=0,0,$E$29/$C$29) | G29: CP Ops
A30: S4 | B30: Sales Team Ops | C30: 120 | D30: 0 | E30: =$C$30-$D$30 | F30: =IF($C$30=0,0,$E$30/$C$30) | G30: Sales
A31: S4 | B31: Site Event Marketing | C31: 25 | D31: 0 | E31: =$C$31-$D$31 | F31: =IF($C$31=0,0,$E$31/$C$31) | G31: Events
B32: Stage 4 Subtotal | C32: =SUM($C$25:$C$31) | D32: =SUM($D$25:$D$31) | E32: =$C$32-$D$32 | F32: =IF($C$32=0,0,$E$32/$C$32)
B34: GRAND TOTAL | C34: =$C$9+$C$17+$C$23+$C$32 | D34: =$D$9+$D$17+$D$23+$D$32 | E34: =$C$34-$D$34 | F34: =IF($C$34=0,0,$E$34/$C$34)

Sheet CAC & Marketing Analysis
A1: CAC & Marketing Funnel Analysis
A2: CPL, CAC, and ROAS calculated via formulas. Adjust budget/leads to see impact.
A4: Channel | B4: Monthly Budget (Lakhs) | C4: Leads/Mo | D4: Site Visits/Mo | E4: Conversions/Mo | F4: CPL (Rs) | G4: CAC per Unit (Lakhs) | H4: Channel Revenue (Cr/mo) | I4: ROAS
A5: Google Search (SEM) | B5: 12 | C5: 800 | D5: 48 | E5: 8 | F5: =IF($C$5=0,0,$B$5*100000/$C$5) | G5: =IF($E$5=0,0,$B$5/$E$5) | H5: =$E$5*'Assumptions'!$B$76 | I5: =IF($B$5=0,0,$H$5*100/$B$5)
A6: Meta (FB/Instagram) | B6: 8 | C6: 1200 | D6: 36 | E6: 5 | F6: =IF($C$6=0,0,$B$6*100000/$C$6) | G6: =IF($E$6=0,0,$B$6/$E$6) | H6: =$E$6*'Assumptions'!$B$76 | I6: =IF($B$6=0,0,$H$6*100/$B$6)
A7: Google Display & YouTube | B7: 5 | C7: 2000 | D7: 20 | E7: 3 | F7: =IF($C$7=0,0,$B$7*100000/$C$7) | G7: =IF($E$7=0,0,$B$7/$E$7) | H7: =$E$7*'Assumptions'!$B$76 | I7: =IF($B$7=0,0,$H$7*100/$B$7)
A8: CP Broker Network | B8: 15 | C8: 300 | D8: 90 | E8: 12 | F8: =IF($C$8=0,0,$B$8*100000/$C$8) | G8: =IF($E$8=0,0,$B$8/$E$8) | H8: =$E$8*'Assumptions'!$B$76 | I8: =IF($B$8=0,0,$H$8*100/$B$8)
A9: Organic / Walk-in Genie AI | B9: 2 | C9: 400 | D9: 60 | E9: 6 | F9: =IF($C$9=0,0,$B$9*100000/$C$9) | G9: =IF($E$9=0,0,$B$9/$E$9) | H9: =$E$9*'Assumptions'!$B$76 | I9: =IF($B$9=0,0,$H$9*100/$B$9)
A10: n8n Lead Revival (Phoenix) | B10: 1.5 | C10: 150 | D10: 25 | E10: 3 | F10: =IF($C$10=0,0,$B$10*100000/$C$10) | G10: =IF($E$10=0,0,$B$10/$E$10) | H10: =$E$10*'Assumptions'!$B$76 | I10: =IF($B$10=0,0,$H$10*100/$B$10)
A11: Local OOH / Print | B11: 6 | C11: 500 | D11: 15 | E11: 2 | F11: =IF($C$11=0,0,$B$11*100000/$C$11) | G11: =IF($E$11=0,0,$B$11/$E$11) | H11: =$E$11*'Assumptions'!$B$76 | I11: =IF($B$11=0,0,$H$11*100/$B$11)
A12: Referral Program | B12: 1 | C12: 50 | D12: 15 | E12: 2 | F12: =IF($C$12=0,0,$B$12*100000/$C$12) | G12: =IF($E$12=0,0,$B$12/$E$12) | H12: =$E$12*'Assumptions'!$B$76 | I12: =IF($B$12=0,0,$H$12*100/$B$12)
A13: BLENDED TOTAL | B13: =SUM($B$5:$B$12) | C13: =SUM($C$5:$C$12) | D13: =SUM($D$5:$D$12) | E13: =SUM($E$5:$E$12) | F13: =IF($C$13=0,0,$B$13*100000/$C$13) | G13: =IF($E$13=0,0,$B$13/$E$13) | H13: =SUM($H$5:$H$12) | I13: =IF($B$13=0,0,$H$13*100/$B$13)
A15: Lead-to-Conversion Funnel
A16: Funnel Stage | B16: Volume | C16: Stage Conv % | D16: Drop-Off % | E16: Cumulative Eff %
A17: Digital Impressions | B17: 5000000 | C17: -- | D17: -- | E17: 1
A18: Clicks / Engagement | B18: 75000 | C18: =$B$18/$B$17 | D18: =1-$C$18 | E18: =$B$18/$B$17
A19: Lead Submissions | B19: 5400 | C19: =$B$19/$B$18 | D19: =1-$C$19 | E19: =$B$19/$B$17
A20: Qualified Leads (MQL) | B20: 2700 | C20: =$B$20/$B$19 | D20: =1-$C$20 | E20: =$B$20/$B$17
A21: Site Visits Booked | B21: 810 | C21: =$B$21/$B$20 | D21: =1-$C$21 | E21: =$B$21/$B$17
A22: Site Visits Done | B22: 450 | C22: =$B$22/$B$21 | D22: =1-$C$22 | E22: =$B$22/$B$17
A23: Booking Intent | B23: 135 | C23: =$B$23/$B$22 | D23: =1-$C$23 | E23: =$B$23/$B$17
A24: Confirmed Bookings | B24: 41 | C24: =$B$24/$B$23 | D24: =1-$C$24 | E24: =$B$24/$B$17

Sheet Sensitivity Analysis
A1: Scenario & Sensitivity Analysis
A2: Bear/Base/Bull/Stress P&L computed via formulas referencing Assumptions
A4: Scenario Multipliers (Change these to adjust scenarios)
A5: Parameter | B5: Bear Factor | C5: Base Factor | D5: Bull Factor | E5: Stress Factor
A6: ASP Multiplier | B6: 0.85 | C6: 1 | D6: 1.12 | E6: 0.78
A7: Velocity Multiplier | B7: 0.67 | C7: 1 | D7: 1.5 | E7: 0.5
A8: Construction Cost Mult. | B8: 1.15 | C8: 1 | D8: 0.9 | E8: 1.25
A9: Interest Rate Mult. | B9: 1.1 | C9: 1 | D9: 0.9 | E9: 1.25
A10: GTM Cost Multiplier | B10: 1.2 | C10: 1 | D10: 0.8 | E10: 1.4
A12: Scenario P&L Summary (Cr) -- All Formulas
A13: Metric | B13: Bear Case | C13: Base Case | D13: Bull Case | E13: Stress Case
A14: Gross Revenue (GTV) | B14: ='Assumptions'!$B$73*$B$6 | C14: ='Assumptions'!$B$73*$C$6 | D14: ='Assumptions'!$B$73*$D$6 | E14: ='Assumptions'!$B$73*$E$6
A15: (-) Land Cost | B15: =-'Assumptions'!$B$78 | C15: =-'Assumptions'!$B$78 | D15: =-'Assumptions'!$B$78 | E15: =-'Assumptions'!$B$78
A16: (-) Construction Cost | B16: =-'Assumptions'!$B$79*$B$8 | C16: =-'Assumptions'!$B$79*$C$8 | D16: =-'Assumptions'!$B$79*$D$8 | E16: =-'Assumptions'!$B$79*$E$8
A17: (-) GTM & Marketing | B17: =-'Assumptions'!$B$88*$B$10 | C17: =-'Assumptions'!$B$88*$C$10 | D17: =-'Assumptions'!$B$88*$D$10 | E17: =-'Assumptions'!$B$88*$E$10
A18: (-) Statutory & Contingency | B18: =-('Assumptions'!$B$31+'Assumptions'!$B$81) | C18: =-('Assumptions'!$B$31+'Assumptions'!$B$81) | D18: =-('Assumptions'!$B$31+'Assumptions'!$B$81) | E18: =-('Assumptions'!$B$31+'Assumptions'!$B$81)
A19: (-) Debt Interest (est.) | B19: =-'Assumptions'!$B$73*$B$6*'Assumptions'!$B$35/100*'Assumptions'!$B$36/100*$B$9*3 | C19: =-'Assumptions'!$B$73*$C$6*'Assumptions'!$B$35/100*'Assumptions'!$B$36/100*$C$9*3 | D19: =-'Assumptions'!$B$73*$D$6*'Assumptions'!$B$35/100*'Assumptions'!$B$36/100*$D$9*3 | E19: =-'Assumptions'!$B$73*$E$6*'Assumptions'!$B$35/100*'Assumptions'!$B$36/100*$E$9*3
A20: Developer Net Profit | B20: =$B$14+$B$15+$B$16+$B$17+$B$18+$B$19 | C20: =$C$14+$C$15+$C$16+$C$17+$C$18+$C$19 | D20: =$D$14+$D$15+$D$16+$D$17+$D$18+$D$19 | E20: =$E$14+$E$15+$E$16+$E$17+$E$18+$E$19
A21: Net Margin % | B21: =$B$20/$B$14 | C21: =$C$20/$C$14 | D21: =$D$20/$D$14 | E21: =$E$20/$E$14
A22: DSCR (est.) | B22: =IF($B$19=0,0,($B$20/3.5)/(-$B$19/3)) | C22: =IF($C$19=0,0,($C$20/3.5)/(-$C$19/3)) | D22: =IF($D$19=0,0,($D$20/3.5)/(-$D$19/3)) | E22: =IF($E$19=0,0,($E$20/3.5)/(-$E$19/3))
A23: Gate 1 Status | B23: =IF($B$21>=0.2,"CLEAR","BLOCKED") | C23: =IF($C$21>=0.2,"CLEAR","BLOCKED") | D23: =IF($D$21>=0.2,"CLEAR","BLOCKED") | E23: =IF($E$21>=0.2,"CLEAR","BLOCKED")

Sheet Risk Mitigation
A1: Risk-Adjusted Stage-Gate Mitigation Costing
A2: Expected Loss = Probability x Potential Loss (formula). Mitigation budget auto-totals.
A4: Risk Category | B4: Stage | C4: Severity | D4: Probability | E4: Potential Loss (Cr) | F4: Expected Loss (Cr) | G4: Mitigation Budget (Lakhs) | H4: Mechanism | I4: Residual Risk
A5: RERA Delays | B5: S2 | C5: HIGH | D5: 0.15 | E5: 25 | F5: =$D$5*$E$5 | G5: 50 | H5: Gate 2 blocks marketing until RERA active | I5: LOW
A6: Broker Apathy | B6: S2 | C6: MEDIUM | D6: 0.25 | E6: 15 | F6: =$D$6*$E$6 | G6: 80 | H6: CP Ranker auto-tiering incentives | I6: LOW
A7: Weak EOI Corpus | B7: S3 | C7: HIGH | D7: 0.2 | E7: 40 | F7: =$D$7*$E$7 | G7: 120 | H7: Gate 3 mandates 12 Cr tokens | I7: MEDIUM
A8: CAC Inflation | B8: S4 | C8: MEDIUM | D8: 0.3 | E8: 12 | F8: =$D$8*$E$8 | G8: 45 | H8: Astra Phoenix lead revival via n8n | I8: LOW
A9: Absorption Lag | B9: S4 | C9: LOW | D9: 0.2 | E9: 8 | F9: =$D$9*$E$9 | G9: 30 | H9: Barbell pricing flex (10-90 plans) | I9: LOW
A10: Cost Overruns | B10: S4 | C10: MEDIUM | D10: 0.25 | E10: 30 | F10: =$D$10*$E$10 | G10: 0 | H10: Developer contingency buffer | I10: MEDIUM
A11: Rate Hikes | B11: All | C11: MEDIUM | D11: 0.2 | E11: 18 | F11: =$D$11*$E$11 | G11: 0 | H11: Velocity acceleration compresses tenure | I11: LOW
A12: TOTALS | E12: =SUM($E$5:$E$11) | F12: =SUM($F$5:$F$11) | G12: =SUM($G$5:$G$11)
A13: Mitigation Budget as % of GTV: | B13: =$G$12/100/'Assumptions'!$B$73

Sheet Anarock Fee Structure
A1: Anarock Engagement Fee Structure & Revenue Model
A2: All fees computed from Assumptions. Change rates to recalculate Anarock revenue.
A4: Fee Component | B4: Rate | C4: Basis | D4: Revenue (Cr) | E4: Payment Trigger
A5: Brokerage Commission | B5: ='Assumptions'!$B$40&"%" | C5: Per unit sale | D5: ='Assumptions'!$B$73*'Assumptions'!$B$40/100 | E5: On each sale closure
A6: Marketing Management Fee | B6: ='Assumptions'!$B$41&"%" | C6: Monthly retainer | D6: ='Assumptions'!$B$73*'Assumptions'!$B$41/100 | E6: Monthly during S3-S4
A7: AI Platform License | B7: ='Assumptions'!$B$42&" L/mo" | C7: SaaS monthly | D7: ='Assumptions'!$B$42*42/100 | E7: Monthly active mandate
A8: CP Mobilization Fee | B8: One-time | C8: On activation | D8: ='Assumptions'!$B$43/100 | E8: Gate 2 clearance
A9: Performance Bonus | B9: ='Assumptions'!$B$44&"%" | C9: Quarterly if >15 u/mo | D9: ='Assumptions'!$B$73*'Assumptions'!$B$44/100 | E9: Quarterly review
A10: TOTAL ANAROCK REVENUE | D10: =SUM($D$5:$D$9)
A11: as % of GTV | D11: =$D$10/'Assumptions'!$B$73
A12: as % of Developer Net Profit | D12: =$D$10/'Assumptions'!$B$92
A15: Anarock Revenue by Phase (Cr)
A16: Period | B16: % of Total Units | C16: Units Sold | D16: Brokerage (Cr) | E16: Marketing Fee (Cr) | F16: Platform Fee (Cr) | G16: Total (Cr)
A17: M1-M2 (Discovery) | B17: 0 | C17: =ROUND($B$17*'Assumptions'!$B$74,0) | D17: =$C$17*'Assumptions'!$B$76*'Assumptions'!$B$40/100 | E17: =$C$17*'Assumptions'!$B$76*'Assumptions'!$B$41/100 | F17: =2*'Assumptions'!$B$42/100 | G17: =$D$17+$E$17+$F$17
A18: M3-M4 (GTM Prep) | B18: 0 | C18: =ROUND($B$18*'Assumptions'!$B$74,0) | D18: =$C$18*'Assumptions'!$B$76*'Assumptions'!$B$40/100 | E18: =$C$18*'Assumptions'!$B$76*'Assumptions'!$B$41/100 | F18: =2*'Assumptions'!$B$42/100 | G18: =$D$18+$E$18+$F$18
A19: M5 (Soft Launch) | B19: 0.15 | C19: =ROUND($B$19*'Assumptions'!$B$74,0) | D19: =$C$19*'Assumptions'!$B$76*'Assumptions'!$B$40/100 | E19: =$C$19*'Assumptions'!$B$76*'Assumptions'!$B$41/100 | F19: =1*'Assumptions'!$B$42/100 | G19: =$D$19+$E$19+$F$19
A20: M6-M12 (Launch) | B20: 0.27 | C20: =ROUND($B$20*'Assumptions'!$B$74,0) | D20: =$C$20*'Assumptions'!$B$76*'Assumptions'!$B$40/100 | E20: =$C$20*'Assumptions'!$B$76*'Assumptions'!$B$41/100 | F20: =7*'Assumptions'!$B$42/100 | G20: =$D$20+$E$20+$F$20
A21: M13-M24 (Sustenance) | B21: 0.31 | C21: =ROUND($B$21*'Assumptions'!$B$74,0) | D21: =$C$21*'Assumptions'!$B$76*'Assumptions'!$B$40/100 | E21: =$C$21*'Assumptions'!$B$76*'Assumptions'!$B$41/100 | F21: =12*'Assumptions'!$B$42/100 | G21: =$D$21+$E$21+$F$21
A22: M25-M36 (Sustenance) | B22: 0.205 | C22: =ROUND($B$22*'Assumptions'!$B$74,0) | D22: =$C$22*'Assumptions'!$B$76*'Assumptions'!$B$40/100 | E22: =$C$22*'Assumptions'!$B$76*'Assumptions'!$B$41/100 | F22: =12*'Assumptions'!$B$42/100 | G22: =$D$22+$E$22+$F$22
A23: M37-M42 (Wrapex) | B23: 0.065 | C23: =ROUND($B$23*'Assumptions'!$B$74,0) | D23: =$C$23*'Assumptions'!$B$76*'Assumptions'!$B$40/100 | E23: =$C$23*'Assumptions'!$B$76*'Assumptions'!$B$41/100 | F23: =6*'Assumptions'!$B$42/100 | G23: =$D$23+$E$23+$F$23
A24: TOTAL | B24: =SUM($B$17:$B$23) | C24: =SUM($C$17:$C$23) | D24: =SUM($D$17:$D$23) | E24: =SUM($E$17:$E$23) | F24: =SUM($F$17:$F$23) | G24: =SUM($G$17:$G$23)
